Traceback (most recent call last):
  File "f:\jinzhu\conda_env\luto\Lib\site-packages\jupyter_cache\executors\utils.py", line 58, in single_nb_execution
    executenb(
  File "f:\jinzhu\conda_env\luto\Lib\site-packages\nbclient\client.py", line 1314, in execute
    return NotebookClient(nb=nb, resources=resources, km=km, **kwargs).execute()
           ^^^^^^^^^^^^^^^^^^^^^^^^^^^^^^^^^^^^^^^^^^^^^^^^^^^^^^^^^^^^^^^^^^^^^
  File "f:\jinzhu\conda_env\luto\Lib\site-packages\jupyter_core\utils\__init__.py", line 165, in wrapped
    return loop.run_until_complete(inner)
           ^^^^^^^^^^^^^^^^^^^^^^^^^^^^^^
  File "f:\jinzhu\conda_env\luto\Lib\asyncio\base_events.py", line 687, in run_until_complete
    return future.result()
           ^^^^^^^^^^^^^^^
  File "f:\jinzhu\conda_env\luto\Lib\site-packages\nbclient\client.py", line 709, in async_execute
    await self.async_execute_cell(
  File "f:\jinzhu\conda_env\luto\Lib\site-packages\nbclient\client.py", line 1062, in async_execute_cell
    await self._check_raise_for_error(cell, cell_index, exec_reply)
  File "f:\jinzhu\conda_env\luto\Lib\site-packages\nbclient\client.py", line 918, in _check_raise_for_error
    raise CellExecutionError.from_cell_and_msg(cell, exec_reply_content)
nbclient.exceptions.CellExecutionError: An error occurred while executing the following cell:
------------------
# REMOVE

# Define year, lu_code
year_begin = 2010
year_target = 2050
lu_code = 25 # Winter cereals
lu_desc = data.AGRICULTURAL_LANDUSES[lu_code]

# Parameters to save xarray
output_dir = 'luto/tools/Manual_jupyter_books/outputs'
encoding={'data': {"compression": "gzip", "compression_opts": 9,  "dtype": 'float32'}}

# Get the lumap
lumap = mrj_to_xr(data, data.ag_dvars[year_begin])

lu_arr = lumap.sel(lu=lu_desc)
lu_arr_dry = lumap.sel(lm='dry')
lu_arr_irr = lumap.sel(lm='irr')

lu_mask = arr_to_xr(data, np.ones_like(lumap)) == 1
lu_area = arr_to_xr(data, data.REAL_AREA)


# Save to disk
lu_arr_dry.name = 'data'
lu_arr_irr.name = 'data'

lu_arr_dry.to_netcdf(f'{output_dir}/lu_arr_dry.nc', engine='h5netcdf', encoding=encoding)
lu_arr_irr.to_netcdf(f'{output_dir}/lu_arr_irr.nc', engine='h5netcdf', encoding=encoding)
------------------


[1;31m---------------------------------------------------------------------------[0m
[1;31mNameError[0m                                 Traceback (most recent call last)
Cell [1;32mIn[2], line 7[0m
[0;32m      5[0m year_target [38;5;241m=[39m [38;5;241m2050[39m
[0;32m      6[0m lu_code [38;5;241m=[39m [38;5;241m25[39m [38;5;66;03m# Winter cereals[39;00m
[1;32m----> 7[0m lu_desc [38;5;241m=[39m [43mdata[49m[38;5;241m.[39mAGRICULTURAL_LANDUSES[lu_code]
[0;32m      9[0m [38;5;66;03m# Parameters to save xarray[39;00m
[0;32m     10[0m output_dir [38;5;241m=[39m [38;5;124m'[39m[38;5;124mluto/tools/Manual_jupyter_books/outputs[39m[38;5;124m'[39m

[1;31mNameError[0m: name 'data' is not defined

