Traceback (most recent call last):
  File "f:\jinzhu\conda_env\luto\Lib\site-packages\jupyter_cache\executors\utils.py", line 58, in single_nb_execution
    executenb(
  File "f:\jinzhu\conda_env\luto\Lib\site-packages\nbclient\client.py", line 1314, in execute
    return NotebookClient(nb=nb, resources=resources, km=km, **kwargs).execute()
           ^^^^^^^^^^^^^^^^^^^^^^^^^^^^^^^^^^^^^^^^^^^^^^^^^^^^^^^^^^^^^^^^^^^^^
  File "f:\jinzhu\conda_env\luto\Lib\site-packages\jupyter_core\utils\__init__.py", line 165, in wrapped
    return loop.run_until_complete(inner)
           ^^^^^^^^^^^^^^^^^^^^^^^^^^^^^^
  File "f:\jinzhu\conda_env\luto\Lib\asyncio\base_events.py", line 687, in run_until_complete
    return future.result()
           ^^^^^^^^^^^^^^^
  File "f:\jinzhu\conda_env\luto\Lib\site-packages\nbclient\client.py", line 709, in async_execute
    await self.async_execute_cell(
  File "f:\jinzhu\conda_env\luto\Lib\site-packages\nbclient\client.py", line 1062, in async_execute_cell
    await self._check_raise_for_error(cell, cell_index, exec_reply)
  File "f:\jinzhu\conda_env\luto\Lib\site-packages\nbclient\client.py", line 918, in _check_raise_for_error
    raise CellExecutionError.from_cell_and_msg(cell, exec_reply_content)
nbclient.exceptions.CellExecutionError: An error occurred while executing the following cell:
------------------
beec_rev = arr_to_xr(data, data.BECCS_REV_AUD_HA_YR)
beec_rev.plot(vmin=0)
------------------


[1;31m---------------------------------------------------------------------------[0m
[1;31mNameError[0m                                 Traceback (most recent call last)
Cell [1;32mIn[2], line 1[0m
[1;32m----> 1[0m beec_rev [38;5;241m=[39m arr_to_xr([43mdata[49m, data[38;5;241m.[39mBECCS_REV_AUD_HA_YR)
[0;32m      2[0m beec_rev[38;5;241m.[39mplot(vmin[38;5;241m=[39m[38;5;241m0[39m)

[1;31mNameError[0m: name 'data' is not defined

